<robot name="scara_control">
    <!-- Global Material Definitions -->
    <material name="aluminium">
        <color rgba="0.8 0.8 0.8 1.0" />
    </material>
    <material name="steel">
        <color rgba="0.6 0.6 0.6 1.0" />
    </material>
    <material name="plastic">
        <color rgba="0.1 0.1 0.1 1.0" />
    </material>
    <material name="glass">
        <color rgba="0.7 0.7 1.0 0.5" />
    </material>

    <!-- Base Link -->
    <link name="base_link">
        <visual>
            <origin xyz="0 0 0" rpy="0 0 0" />
            <geometry>
                <mesh filename="scara_meshes/base_link.STL" scale="5 5 5" />
            </geometry>
            <material name="steel" />
        </visual>
        <collision>
            <origin xyz="0 0 0" rpy="0 0 0" />
            <geometry>
                <mesh filename="scara_meshes/base_link.STL" scale="5 5 5" />
            </geometry>
        </collision>
    </link>

    <!-- Joint 1 -->
    <joint name="joint_1" type="revolute">
        <origin xyz="0.325 0 0" rpy="0 0 0" />
        <parent link="base_link" />
        <child link="link_1" />
        <axis xyz="0 0 1" />
        <limit lower="-3.28" upper="-0.20" effort="300" velocity="2.53" />
    </joint>

    <!-- Link 1 -->
    <link name="link_1">
        <visual>
            <origin xyz="0 0 0" rpy="0 0 0" />
            <geometry>
                <mesh filename="scara_meshes/link_1.STL" scale="5 5 5" />
            </geometry>
            <material name="aluminium" />
        </visual>
        <collision>
            <origin xyz="0 0 0" rpy="0 0 0" />
            <geometry>
                <mesh filename="scara_meshes/link_1.STL" scale="5 5 5" />
            </geometry>
        </collision>
    </link>

    <!-- Joint 2 -->
    <joint name="joint_2" type="revolute">
        <origin xyz="0.140575 -0.81295 1.1675" rpy="0 0 0" />
        <parent link="link_1" />
        <child link="link_2" />
        <axis xyz="0 0 1" />
        <limit lower="-2.68" upper="0.79" effort="200" velocity="2.53" />
    </joint>

    <!-- Link 2 -->
    <link name="link_2">
        <visual>
            <origin xyz="0 0 0" rpy="0 0 0" />
            <geometry>
                <mesh filename="scara_meshes/link_2.STL" scale="5 5 5" />
            </geometry>
            <material name="aluminium" />
        </visual>
        <collision>
            <origin xyz="0 0 0" rpy="0 0 0" />
            <geometry>
                <mesh filename="scara_meshes/link_2.STL" scale="5 5 5" />
            </geometry>
        </collision>
    </link>

    <!-- Joint 3 -->
    <joint name="joint_3" type="prismatic">
        <origin xyz="0.5419 -0.314655 0.193" rpy="0 0 0" />
        <parent link="link_2" />
        <child link="link_3" />
        <axis xyz="0 0 1" />
        <limit lower="-0.4" upper="0" effort="50" velocity="1" />
    </joint>

    <!-- Link 3 -->
    <link name="link_3">
        <visual>
            <origin xyz="0 0 0" rpy="0 0 0" />
            <geometry>
                <mesh filename="scara_meshes/link_3.STL" scale="5 5 5" />
            </geometry>
            <material name="aluminium" />
        </visual>
        <collision>
            <origin xyz="0 0 0" rpy="0 0 0" />
            <geometry>
                <mesh filename="scara_meshes/link_3.STL" scale="5 5 5" />
            </geometry>
        </collision>
    </link>

</robot>
